<robot name="scara_robot">

  <!-- Materiales -->
  <material name="blue">
    <color rgba="0 0 1 1"/>
  </material>
  <material name="white">
    <color rgba="1 1 1 1"/>
  </material>

  <!-- Base del robot -->
  <link name="base_link">
    <visual>
      <origin xyz="0 0 0.2" rpy="0 0 0"/>
      <geometry>
        <cylinder radius="0.1" length="0.4"/>
      </geometry>
      <material name="blue"/>
    </visual>
  </link>

  <!-- Primer brazo -->
  <link name="arm_1">
    <visual>
      <geometry>
        <box size="0.5 0.05 0.05"/>
      </geometry>
      <material name="white"/>
    </visual>
  </link>

  <joint name="joint_1" type="revolute">
    <parent link="base_link"/>
    <child link="arm_1"/>
    <origin xyz="0 0 0.4" rpy="0 0 0"/>
    <axis xyz="0 0 1"/>
    <limit effort="50" velocity="1.5" lower="-3.14" upper="3.14"/>
  </joint>

  <!-- Segundo brazo -->
  <link name="arm_2">
    <visual>
      <geometry>
        <box size="0.50 0.05 0.05"/>
      </geometry>
      <material name="white"/>
    </visual>
  </link>

  <joint name="joint_2" type="revolute">
    <parent link="arm_1"/>
    <child link="arm_2"/>
    <origin xyz="0.23 0 0" rpy="0 0 0"/>
    <axis xyz="0 0 1"/>
    <limit effort="50" velocity="1.5" lower="-2.5" upper="2.5"/>
  </joint>

  <!-- Eje vertical -->
  <link name="vertical_axis">
    <visual>
      <geometry>
        <cylinder radius="0.03" length="0.15"/>
      </geometry>
      <material name="blue"/>
    </visual>
  </link>

  <!-- Herramienta final -->
  <link name="end_effector">
    <visual>
      <geometry>
        <cylinder radius="0.02" length="0.14"/>
      </geometry>
      <material name="white"/>
    </visual>
  </link>

  <joint name="joint_3" type="fixed">
    <parent link="arm_2"/>
    <child link="vertical_axis"/>
    <origin xyz="0.25 0 0" rpy="0 0 0"/>
  </joint>

  <joint name="joint_4" type="prismatic">
    <parent link="vertical_axis"/>
    <child link="end_effector"/>
    <origin xyz="0 0 -0.1" rpy="0 0 0"/>    
    <axis xyz="0 0 -1"/>
    <limit effort="30" velocity="0.5" lower="-0.1" upper="0"/>
    
  </joint>

</robot>
